<?xml version="1.0" ?>
<!-- MuJoCo model for FANUC R2000IC165F -->
<!-- Auto-generated from fanuc-industrial/fanuc_r2000ic_support -->
<mujoco model="r2000ic165f">
  <compiler angle="radian" autolimits="true"/>

  <default>
    <default class="r2000ic165f">
      <joint damping="100" frictionloss="10" armature="1"/>
      <position kp="1000" kv="100"/>
      <default class="visual">
        <geom type="mesh" contype="0" conaffinity="0" group="2"/>
      </default>
      <default class="collision">
        <geom type="mesh" group="3"/>
      </default>
    </default>
  </default>

  <asset>
    <mesh name="base_link_visual" file="../../fanuc-industrial/fanuc_r2000ic_support/meshes/r2000ic165f/visual/base_link.stl"/>
    <mesh name="base_link_collision" file="../../fanuc-industrial/fanuc_r2000ic_support/meshes/r2000ic165f/collision/base_link.stl"/>
    <mesh name="link_1_visual" file="../../fanuc-industrial/fanuc_r2000ic_support/meshes/r2000ic165f/visual/link_1.stl"/>
    <mesh name="link_1_collision" file="../../fanuc-industrial/fanuc_r2000ic_support/meshes/r2000ic165f/collision/link_1.stl"/>
    <mesh name="link_2_visual" file="../../fanuc-industrial/fanuc_r2000ic_support/meshes/r2000ic165f/visual/link_2.stl"/>
    <mesh name="link_2_collision" file="../../fanuc-industrial/fanuc_r2000ic_support/meshes/r2000ic165f/collision/link_2.stl"/>
    <mesh name="link_3_visual" file="../../fanuc-industrial/fanuc_r2000ic_support/meshes/r2000ic165f/visual/link_3.stl"/>
    <mesh name="link_3_collision" file="../../fanuc-industrial/fanuc_r2000ic_support/meshes/r2000ic165f/collision/link_3.stl"/>
    <mesh name="link_4_visual" file="../../fanuc-industrial/fanuc_r2000ic_support/meshes/r2000ic165f/visual/link_4.stl"/>
    <mesh name="link_4_collision" file="../../fanuc-industrial/fanuc_r2000ic_support/meshes/r2000ic165f/collision/link_4.stl"/>
    <mesh name="link_5_visual" file="../../fanuc-industrial/fanuc_r2000ic_support/meshes/r2000ic165f/visual/link_5.stl"/>
    <mesh name="link_5_collision" file="../../fanuc-industrial/fanuc_r2000ic_support/meshes/r2000ic165f/collision/link_5.stl"/>
    <mesh name="link_6_visual" file="../../fanuc-industrial/fanuc_r2000ic_support/meshes/r2000ic165f/visual/link_6.stl"/>
    <mesh name="link_6_collision" file="../../fanuc-industrial/fanuc_r2000ic_support/meshes/r2000ic165f/collision/link_6.stl"/>
  </asset>

  <worldbody>
    <body name="base_link" childclass="r2000ic165f">
      <inertial pos="0 0 0" mass="1.0" diaginertia="0.01 0.01 0.01"/>
      <geom class="visual" mesh="base_link_visual" rgba="0.400 0.400 0.400 1.000"/>
      <geom class="collision" mesh="base_link_collision"/>
      <body name="link_1" pos="0 0 0.670" childclass="r2000ic165f">
        <joint name="joint_1" type="hinge" axis="0 0 1" range="-3.2289 3.2289"/>
        <inertial pos="0 0 0" mass="1.0" diaginertia="0.01 0.01 0.01"/>
        <geom class="visual" mesh="link_1_visual" rgba="0.960 0.760 0.130 1.000"/>
        <geom class="collision" mesh="link_1_collision"/>
        <body name="link_2" pos="0.312 0 0" childclass="r2000ic165f">
          <joint name="joint_2" type="hinge" axis="0 1 0" range="-1.0472 1.3265"/>
          <inertial pos="0 0 0" mass="1.0" diaginertia="0.01 0.01 0.01"/>
          <geom class="visual" mesh="link_2_visual" rgba="0.960 0.760 0.130 1.000"/>
          <geom class="collision" mesh="link_2_collision"/>
          <body name="link_3" pos="0 0 1.075" childclass="r2000ic165f">
            <joint name="joint_3" type="hinge" axis="0 -1 0" range="-2.3038 3.1416"/>
            <inertial pos="0 0 0" mass="1.0" diaginertia="0.01 0.01 0.01"/>
            <geom class="visual" mesh="link_3_visual" rgba="0.960 0.760 0.130 1.000"/>
            <geom class="collision" mesh="link_3_collision"/>
            <body name="link_4" pos="0 0 0.225" childclass="r2000ic165f">
              <joint name="joint_4" type="hinge" axis="-1 0 0" range="-6.2832 6.2832"/>
              <inertial pos="0 0 0" mass="1.0" diaginertia="0.01 0.01 0.01"/>
              <geom class="visual" mesh="link_4_visual" rgba="0.960 0.760 0.130 1.000"/>
              <geom class="collision" mesh="link_4_collision"/>
              <body name="link_5" pos="1.280 0 0" childclass="r2000ic165f">
                <joint name="joint_5" type="hinge" axis="0 -1 0" range="-2.1817 2.1817"/>
                <inertial pos="0 0 0" mass="1.0" diaginertia="0.01 0.01 0.01"/>
                <geom class="visual" mesh="link_5_visual" rgba="0.960 0.760 0.130 1.000"/>
                <geom class="collision" mesh="link_5_collision"/>
                <body name="link_6" pos="0.215 0 0" childclass="r2000ic165f">
                  <joint name="joint_6" type="hinge" axis="-1 0 0" range="-6.2832 6.2832"/>
                  <inertial pos="0 0 0" mass="1.0" diaginertia="0.01 0.01 0.01"/>
                  <geom class="visual" mesh="link_6_visual" rgba="0.150 0.150 0.150 1.000"/>
                  <geom class="collision" mesh="link_6_collision"/>
                </body>
              </body>
            </body>
          </body>
        </body>
      </body>
    </body>
  </worldbody>

  <actuator>
    <position name="joint_1_actuator" joint="joint_1" class="r2000ic165f"/>
    <position name="joint_2_actuator" joint="joint_2" class="r2000ic165f"/>
    <position name="joint_3_actuator" joint="joint_3" class="r2000ic165f"/>
    <position name="joint_4_actuator" joint="joint_4" class="r2000ic165f"/>
    <position name="joint_5_actuator" joint="joint_5" class="r2000ic165f"/>
    <position name="joint_6_actuator" joint="joint_6" class="r2000ic165f"/>
  </actuator>
</mujoco>