<?xml version="1.0" ?>
<!-- MuJoCo model for FANUC CR35IA -->
<!-- Auto-generated from fanuc-industrial/fanuc_cr35ia_support -->
<mujoco model="cr35ia">
  <compiler angle="radian" autolimits="true"/>

  <default>
    <default class="cr35ia">
      <joint damping="100" frictionloss="10" armature="1"/>
      <position kp="1000" kv="100"/>
      <default class="visual">
        <geom type="mesh" contype="0" conaffinity="0" group="2"/>
      </default>
      <default class="collision">
        <geom type="mesh" group="3"/>
      </default>
    </default>
  </default>

  <asset>
    <mesh name="base_link_visual" file="../../fanuc-industrial/fanuc_cr35ia_support/meshes/cr35ia/visual/base_link.stl"/>
    <mesh name="base_link_collision" file="../../fanuc-industrial/fanuc_cr35ia_support/meshes/cr35ia/collision/base_link.stl"/>
    <mesh name="link_1_visual" file="../../fanuc-industrial/fanuc_cr35ia_support/meshes/cr35ia/visual/link_1.stl"/>
    <mesh name="link_1_collision" file="../../fanuc-industrial/fanuc_cr35ia_support/meshes/cr35ia/collision/link_1.stl"/>
    <mesh name="link_2_visual" file="../../fanuc-industrial/fanuc_cr35ia_support/meshes/cr35ia/visual/link_2.stl"/>
    <mesh name="link_2_collision" file="../../fanuc-industrial/fanuc_cr35ia_support/meshes/cr35ia/collision/link_2.stl"/>
    <mesh name="link_3_visual" file="../../fanuc-industrial/fanuc_cr35ia_support/meshes/cr35ia/visual/link_3.stl"/>
    <mesh name="link_3_collision" file="../../fanuc-industrial/fanuc_cr35ia_support/meshes/cr35ia/collision/link_3.stl"/>
    <mesh name="link_4_visual" file="../../fanuc-industrial/fanuc_cr35ia_support/meshes/cr35ia/visual/link_4.stl"/>
    <mesh name="link_4_collision" file="../../fanuc-industrial/fanuc_cr35ia_support/meshes/cr35ia/collision/link_4.stl"/>
    <mesh name="link_5_visual" file="../../fanuc-industrial/fanuc_cr35ia_support/meshes/cr35ia/visual/link_5.stl"/>
    <mesh name="link_5_collision" file="../../fanuc-industrial/fanuc_cr35ia_support/meshes/cr35ia/collision/link_5.stl"/>
    <mesh name="link_6_visual" file="../../fanuc-industrial/fanuc_cr35ia_support/meshes/cr35ia/visual/link_6.stl"/>
    <mesh name="link_6_collision" file="../../fanuc-industrial/fanuc_cr35ia_support/meshes/cr35ia/collision/link_6.stl"/>
  </asset>

  <worldbody>
    <body name="base_link" childclass="cr35ia">
      <inertial pos="0 0 0" mass="1.0" diaginertia="0.01 0.01 0.01"/>
      <geom class="visual" mesh="base_link_visual" rgba="0.278 0.278 0.278 1.000"/>
      <geom class="collision" mesh="base_link_collision"/>
      <body name="link_1" pos="0 0 1.180" childclass="cr35ia">
        <joint name="joint_1" type="hinge" axis="0 0 1" range="-2.9670 2.9670"/>
        <inertial pos="0 0 0" mass="1.0" diaginertia="0.01 0.01 0.01"/>
        <geom class="visual" mesh="link_1_visual" rgba="0.000 0.608 0.275 1.000"/>
        <geom class="collision" mesh="link_1_collision"/>
        <body name="link_2" pos="0.150 0 0" childclass="cr35ia">
          <joint name="joint_2" type="hinge" axis="0 1 0" range="-0.7853 2.0943"/>
          <inertial pos="0 0 0" mass="1.0" diaginertia="0.01 0.01 0.01"/>
          <geom class="visual" mesh="link_2_visual" rgba="0.000 0.608 0.275 1.000"/>
          <geom class="collision" mesh="link_2_collision"/>
          <body name="link_3" pos="0 0 0.790" childclass="cr35ia">
            <joint name="joint_3" type="hinge" axis="0 -1 0" range="-2.1450 2.3561"/>
            <inertial pos="0 0 0" mass="1.0" diaginertia="0.01 0.01 0.01"/>
            <geom class="visual" mesh="link_3_visual" rgba="0.000 0.608 0.275 1.000"/>
            <geom class="collision" mesh="link_3_collision"/>
            <body name="link_4" pos="0 0 0.150" childclass="cr35ia">
              <joint name="joint_4" type="hinge" axis="-1 0 0" range="-3.4906 3.4906"/>
              <inertial pos="0 0 0" mass="1.0" diaginertia="0.01 0.01 0.01"/>
              <geom class="visual" mesh="link_4_visual" rgba="0.000 0.608 0.275 1.000"/>
              <geom class="collision" mesh="link_4_collision"/>
              <body name="link_5" pos="0.860 0 0" childclass="cr35ia">
                <joint name="joint_5" type="hinge" axis="0 -1 0" range="-1.9198 1.9198"/>
                <inertial pos="0 0 0" mass="1.0" diaginertia="0.01 0.01 0.01"/>
                <geom class="visual" mesh="link_5_visual" rgba="0.860 0.850 0.810 1.000"/>
                <geom class="collision" mesh="link_5_collision"/>
                <body name="link_6" pos="0.100 0 0" childclass="cr35ia">
                  <joint name="joint_6" type="hinge" axis="-1 0 0" range="-7.8539 7.8539"/>
                  <inertial pos="0 0 0" mass="1.0" diaginertia="0.01 0.01 0.01"/>
                  <geom class="visual" mesh="link_6_visual" rgba="0.150 0.150 0.150 1.000"/>
                  <geom class="collision" mesh="link_6_collision"/>
                </body>
              </body>
            </body>
          </body>
        </body>
      </body>
    </body>
  </worldbody>

  <contact>
    <!-- Exclude collisions between adjacent links (parent-child pairs) -->
    <exclude body1="base_link" body2="link_1"/>
    <exclude body1="link_1" body2="link_2"/>
    <exclude body1="link_2" body2="link_3"/>
    <exclude body1="link_3" body2="link_4"/>
    <exclude body1="link_4" body2="link_5"/>
    <exclude body1="link_5" body2="link_6"/>
  </contact>

  <actuator>
    <position name="joint_1_actuator" joint="joint_1" class="cr35ia"/>
    <position name="joint_2_actuator" joint="joint_2" class="cr35ia"/>
    <position name="joint_3_actuator" joint="joint_3" class="cr35ia"/>
    <position name="joint_4_actuator" joint="joint_4" class="cr35ia"/>
    <position name="joint_5_actuator" joint="joint_5" class="cr35ia"/>
    <position name="joint_6_actuator" joint="joint_6" class="cr35ia"/>
  </actuator>
</mujoco>